<?xml version="1.0" ?> 
<robot name="atks" xmlns:xacro="http://ros.org/wiki/xacro"> 
 <link name="base"/> 
  <joint name="base_edge0_linkP" type="fixed">  
    <parent link="base"/>   
    <child link="edge0_linkP"/>  
    <origin xyz="0.000000 0.000000 0.000000" rpy="0.000000 0.000000 0.000000"/>   
  </joint>   
  <link name="edge0_linkP">   
      <visual>   
       <geometry>    
         <cylinder length="0.000000" radius="0.000000"/>    
       </geometry>   
        <origin xyz="0.000000 0.000000 0.000000" rpy="0.000000 0.000000 0.000000"/>   
       <material name="Material_1"> 
         <color rgba="0.000000 0.000000 0.000000 1.000000"/> 
       </material>  
     </visual>   
   </link>    
  <joint name="edge0_linkP_edge0_link0Z_1" type="fixed">  
    <parent link="edge0_linkP"/>   
    <child link="edge0_link0Z_1"/>  
    <origin xyz="0.000000 0.000000 0.000000" rpy="0.000000 0.000000 0.000000"/>   
  </joint>   
  <link name="edge0_link0Z_1">   
      <visual>   
       <geometry>    
         <cylinder length="187.382458" radius="1.500000"/>    
       </geometry>   
        <origin xyz="0.000000 0.000000 93.691229" rpy="0.000000 0.000000 0.000000"/>   
       <material name="Material_2"> 
         <color rgba="0.541176 0.168627 0.886275 1.000000"/> 
       </material>  
     </visual>   
   </link>    
  <joint name="edge0_link0Z_1_edge0_link0X_1" type="fixed">  
    <parent link="edge0_link0Z_1"/>   
    <child link="edge0_link0X_1"/>  
    <origin xyz="0.000000 0.000000 187.382458" rpy="0.000000 0.000000 -1.363798"/>   
  </joint>   
  <link name="edge0_link0X_1">   
      <visual>   
       <geometry>    
         <cylinder length="75.413387" radius="1.000000"/>    
       </geometry>   
        <origin xyz="37.706693 0.000000 0.000000" rpy="0.000000 1.570796 0.000000"/>   
       <material name="Material_3"> 
         <color rgba="0.541176 0.168627 0.886275 1.000000"/> 
       </material>  
     </visual>   
   </link>    
  <joint name="edge0_link0X_1_edge1_linkP" type="revolute"> 
   <parent link="edge0_link0X_1"/>    
    <child link="edge1_linkP"/>   
    <origin xyz="75.413387 0.000000 0.000000" rpy="-1.190504 0.000000 0.000000"/>   
   <limit effort="1000.0" lower="-3.14" upper="3.14" velocity="0.5"/>    
  <axis xyz="0.000000 0.000000 1.000000"/>   
   </joint> 
  <link name="edge1_linkP">   
      <visual>   
       <geometry>    
         <cylinder length="0.000000" radius="0.000000"/>    
       </geometry>   
        <origin xyz="0.000000 0.000000 0.000000" rpy="0.000000 0.000000 0.000000"/>   
       <material name="Material_4"> 
         <color rgba="0.541176 0.168627 0.886275 1.000000"/> 
       </material>  
     </visual>   
   </link>    
  <joint name="edge1_linkP_edge1_link0Z_2" type="fixed">  
    <parent link="edge1_linkP"/>   
    <child link="edge1_link0Z_2"/>  
    <origin xyz="0.000000 0.000000 0.000000" rpy="0.000000 0.000000 0.000000"/>   
  </joint>   
  <joint name="edge1_linkP_edge1_link0Z_3" type="fixed">  
    <parent link="edge1_linkP"/>   
    <child link="edge1_link0Z_3"/>  
    <origin xyz="0.000000 0.000000 0.000000" rpy="0.000000 0.000000 0.000000"/>   
  </joint>   
  <link name="edge1_link0Z_2">   
      <visual>   
       <geometry>    
         <cylinder length="455.135432" radius="1.500000"/>    
       </geometry>   
        <origin xyz="0.000000 0.000000 -227.567716" rpy="0.000000 0.000000 0.000000"/>   
       <material name="Material_5"> 
         <color rgba="0.541176 0.168627 0.886275 1.000000"/> 
       </material>  
     </visual>   
   </link>    
  <joint name="edge1_link0Z_2_edge1_link0X_2" type="fixed">  
    <parent link="edge1_link0Z_2"/>   
    <child link="edge1_link0X_2"/>  
    <origin xyz="0.000000 0.000000 -455.135432" rpy="0.000000 0.000000 2.191051"/>   
  </joint>   
  <link name="edge1_link0X_2">   
      <visual>   
       <geometry>    
         <cylinder length="9.465470" radius="1.000000"/>    
       </geometry>   
        <origin xyz="4.732735 0.000000 0.000000" rpy="0.000000 1.570796 0.000000"/>   
       <material name="Material_6"> 
         <color rgba="0.541176 0.168627 0.886275 1.000000"/> 
       </material>  
     </visual>   
   </link>    
  <joint name="edge1_link0X_2_edge2_linkP" type="revolute"> 
   <parent link="edge1_link0X_2"/>    
    <child link="edge2_linkP"/>   
    <origin xyz="9.465470 0.000000 0.000000" rpy="-2.685371 0.000000 0.000000"/>   
   <limit effort="1000.0" lower="-3.14" upper="3.14" velocity="0.5"/>    
  <axis xyz="0.000000 0.000000 1.000000"/>   
   </joint> 
  <link name="edge2_linkP">   
      <visual>   
       <geometry>    
         <cylinder length="0.000000" radius="0.000000"/>    
       </geometry>   
        <origin xyz="0.000000 0.000000 0.000000" rpy="0.000000 0.000000 0.000000"/>   
       <material name="Material_7"> 
         <color rgba="0.541176 0.168627 0.886275 1.000000"/> 
       </material>  
     </visual>   
   </link>    
  <joint name="edge2_linkP_edge2_link0Z_4" type="fixed">  
    <parent link="edge2_linkP"/>   
    <child link="edge2_link0Z_4"/>  
    <origin xyz="0.000000 0.000000 0.000000" rpy="0.000000 0.000000 0.000000"/>   
  </joint>   
  <joint name="edge2_linkP_edge2_link0Z_5" type="fixed">  
    <parent link="edge2_linkP"/>   
    <child link="edge2_link0Z_5"/>  
    <origin xyz="0.000000 0.000000 0.000000" rpy="0.000000 0.000000 0.000000"/>   
  </joint>   
  <link name="edge2_link0Z_4">   
      <visual>   
       <geometry>    
         <cylinder length="388.862768" radius="1.500000"/>    
       </geometry>   
        <origin xyz="0.000000 0.000000 -194.431384" rpy="0.000000 0.000000 0.000000"/>   
       <material name="Material_8"> 
         <color rgba="0.541176 0.168627 0.886275 1.000000"/> 
       </material>  
     </visual>   
   </link>    
  <joint name="edge2_link0Z_4_edge2_link0X_4" type="fixed">  
    <parent link="edge2_link0Z_4"/>   
    <child link="edge2_link0X_4"/>  
    <origin xyz="0.000000 0.000000 -388.862768" rpy="0.000000 0.000000 -2.704720"/>   
  </joint>   
  <link name="edge2_link0X_4">   
      <visual>   
       <geometry>    
         <cylinder length="8.418095" radius="1.000000"/>    
       </geometry>   
        <origin xyz="4.209048 0.000000 0.000000" rpy="0.000000 1.570796 0.000000"/>   
       <material name="Material_9"> 
         <color rgba="0.541176 0.168627 0.886275 1.000000"/> 
       </material>  
     </visual>   
   </link>    
  <joint name="edge2_link0X_4_edge4_link0Z" type="revolute"> 
   <parent link="edge2_link0X_4"/>    
    <child link="edge4_link0Z"/>   
    <origin xyz="8.418095 0.000000 0.000000" rpy="-2.917646 0.000000 0.000000"/>   
   <limit effort="1000.0" lower="-3.14" upper="3.14" velocity="0.5"/>    
  <axis xyz="0.000000 0.000000 1.000000"/>   
   </joint> 
  <link name="edge4_link0Z">   
      <visual>   
       <geometry>    
         <cylinder length="45.558799" radius="1.500000"/>    
       </geometry>   
        <origin xyz="-0.357320 -0.144080 22.776141" rpy="-0.016914 -0.000000 1.954079"/>   
       <material name="Material_10"> 
         <color rgba="1.000000 1.000000 1.000000 1.000000"/> 
       </material>  
     </visual>   
   </link>    
  <link name="edge2_link0Z_5">   
      <visual>   
       <geometry>    
         <cylinder length="408.452413" radius="1.500000"/>    
       </geometry>   
        <origin xyz="0.000000 0.000000 -204.226207" rpy="0.000000 0.000000 0.000000"/>   
       <material name="Material_11"> 
         <color rgba="0.541176 0.168627 0.886275 1.000000"/> 
       </material>  
     </visual>   
   </link>    
  <joint name="edge2_link0Z_5_edge2_link0X_5" type="fixed">  
    <parent link="edge2_link0Z_5"/>   
    <child link="edge2_link0X_5"/>  
    <origin xyz="0.000000 0.000000 -408.452413" rpy="0.000000 0.000000 -1.171920"/>   
  </joint>   
  <link name="edge2_link0X_5">   
      <visual>   
       <geometry>    
         <cylinder length="14.319392" radius="1.000000"/>    
       </geometry>   
        <origin xyz="7.159696 0.000000 0.000000" rpy="0.000000 1.570796 0.000000"/>   
       <material name="Material_12"> 
         <color rgba="0.541176 0.168627 0.886275 1.000000"/> 
       </material>  
     </visual>   
   </link>    
  <joint name="edge2_link0X_5_edge5_link0Z" type="revolute"> 
   <parent link="edge2_link0X_5"/>    
    <child link="edge5_link0Z"/>   
    <origin xyz="14.319392 0.000000 0.000000" rpy="-0.525040 0.000000 0.000000"/>   
   <limit effort="1000.0" lower="-3.14" upper="3.14" velocity="0.5"/>    
  <axis xyz="0.000000 0.000000 1.000000"/>   
   </joint> 
  <link name="edge5_link0Z">   
      <visual>   
       <geometry>    
         <cylinder length="26.070581" radius="1.500000"/>    
       </geometry>   
        <origin xyz="-1.818539 3.046107 -12.543243" rpy="-2.865958 -0.000000 0.538214"/>   
       <material name="Material_13"> 
         <color rgba="1.000000 1.000000 1.000000 1.000000"/> 
       </material>  
     </visual>   
   </link>    
  <link name="edge1_link0Z_3">   
      <visual>   
       <geometry>    
         <cylinder length="265.723786" radius="1.500000"/>    
       </geometry>   
        <origin xyz="0.000000 0.000000 -132.861893" rpy="0.000000 0.000000 0.000000"/>   
       <material name="Material_14"> 
         <color rgba="0.541176 0.168627 0.886275 1.000000"/> 
       </material>  
     </visual>   
   </link>    
  <joint name="edge1_link0Z_3_edge1_link0X_3" type="fixed">  
    <parent link="edge1_link0Z_3"/>   
    <child link="edge1_link0X_3"/>  
    <origin xyz="0.000000 0.000000 -265.723786" rpy="0.000000 0.000000 2.232001"/>   
  </joint>   
  <link name="edge1_link0X_3">   
      <visual>   
       <geometry>    
         <cylinder length="3.651029" radius="1.000000"/>    
       </geometry>   
        <origin xyz="1.825514 0.000000 0.000000" rpy="0.000000 1.570796 0.000000"/>   
       <material name="Material_15"> 
         <color rgba="0.541176 0.168627 0.886275 1.000000"/> 
       </material>  
     </visual>   
   </link>    
  <joint name="edge1_link0X_3_edge3_linkP" type="revolute"> 
   <parent link="edge1_link0X_3"/>    
    <child link="edge3_linkP"/>   
    <origin xyz="3.651029 0.000000 0.000000" rpy="-2.382186 0.000000 0.000000"/>   
   <limit effort="1000.0" lower="-3.14" upper="3.14" velocity="0.5"/>    
  <axis xyz="0.000000 0.000000 1.000000"/>   
   </joint> 
  <link name="edge3_linkP">   
      <visual>   
       <geometry>    
         <cylinder length="0.000000" radius="0.000000"/>    
       </geometry>   
        <origin xyz="0.000000 0.000000 0.000000" rpy="0.000000 0.000000 0.000000"/>   
       <material name="Material_16"> 
         <color rgba="0.541176 0.168627 0.886275 1.000000"/> 
       </material>  
     </visual>   
   </link>    
  <joint name="edge3_linkP_edge3_link0Z_6" type="fixed">  
    <parent link="edge3_linkP"/>   
    <child link="edge3_link0Z_6"/>  
    <origin xyz="0.000000 0.000000 0.000000" rpy="0.000000 0.000000 0.000000"/>   
  </joint>   
  <joint name="edge3_linkP_edge3_link0Z_7" type="fixed">  
    <parent link="edge3_linkP"/>   
    <child link="edge3_link0Z_7"/>  
    <origin xyz="0.000000 0.000000 0.000000" rpy="0.000000 0.000000 0.000000"/>   
  </joint>   
  <link name="edge3_link0Z_6">   
      <visual>   
       <geometry>    
         <cylinder length="252.531091" radius="1.500000"/>    
       </geometry>   
        <origin xyz="0.000000 0.000000 -126.265545" rpy="0.000000 0.000000 0.000000"/>   
       <material name="Material_17"> 
         <color rgba="0.541176 0.168627 0.886275 1.000000"/> 
       </material>  
     </visual>   
   </link>    
  <joint name="edge3_link0Z_6_edge3_link0X_6" type="fixed">  
    <parent link="edge3_link0Z_6"/>   
    <child link="edge3_link0X_6"/>  
    <origin xyz="0.000000 0.000000 -252.531091" rpy="0.000000 0.000000 -0.719531"/>   
  </joint>   
  <link name="edge3_link0X_6">   
      <visual>   
       <geometry>    
         <cylinder length="5.423200" radius="1.000000"/>    
       </geometry>   
        <origin xyz="2.711600 0.000000 0.000000" rpy="0.000000 1.570796 0.000000"/>   
       <material name="Material_18"> 
         <color rgba="0.541176 0.168627 0.886275 1.000000"/> 
       </material>  
     </visual>   
   </link>    
  <joint name="edge3_link0X_6_edge6_link0Z" type="revolute"> 
   <parent link="edge3_link0X_6"/>    
    <child link="edge6_link0Z"/>   
    <origin xyz="5.423200 0.000000 0.000000" rpy="-0.510186 0.000000 0.000000"/>   
   <limit effort="1000.0" lower="-3.14" upper="3.14" velocity="0.5"/>    
  <axis xyz="0.000000 0.000000 1.000000"/>   
   </joint> 
  <link name="edge6_link0Z">   
      <visual>   
       <geometry>    
         <cylinder length="22.711704" radius="1.500000"/>    
       </geometry>   
        <origin xyz="-0.656083 0.074462 -11.336639" rpy="-3.083414 -0.000000 1.457785"/>   
       <material name="Material_19"> 
         <color rgba="1.000000 1.000000 1.000000 1.000000"/> 
       </material>  
     </visual>   
   </link>    
  <link name="edge3_link0Z_7">   
      <visual>   
       <geometry>    
         <cylinder length="262.576911" radius="1.500000"/>    
       </geometry>   
        <origin xyz="0.000000 0.000000 -131.288455" rpy="0.000000 0.000000 0.000000"/>   
       <material name="Material_20"> 
         <color rgba="0.541176 0.168627 0.886275 1.000000"/> 
       </material>  
     </visual>   
   </link>    
  <joint name="edge3_link0Z_7_edge3_link0X_7" type="fixed">  
    <parent link="edge3_link0Z_7"/>   
    <child link="edge3_link0X_7"/>  
    <origin xyz="0.000000 0.000000 -262.576911" rpy="0.000000 0.000000 -0.864635"/>   
  </joint>   
  <link name="edge3_link0X_7">   
      <visual>   
       <geometry>    
         <cylinder length="8.980921" radius="1.000000"/>    
       </geometry>   
        <origin xyz="4.490461 0.000000 0.000000" rpy="0.000000 1.570796 0.000000"/>   
       <material name="Material_21"> 
         <color rgba="0.541176 0.168627 0.886275 1.000000"/> 
       </material>  
     </visual>   
   </link>    
  <joint name="edge3_link0X_7_edge7_link0Z" type="revolute"> 
   <parent link="edge3_link0X_7"/>    
    <child link="edge7_link0Z"/>   
    <origin xyz="8.980921 0.000000 0.000000" rpy="2.466143 0.000000 0.000000"/>   
   <limit effort="1000.0" lower="-3.14" upper="3.14" velocity="0.5"/>    
  <axis xyz="0.000000 0.000000 1.000000"/>   
   </joint> 
  <link name="edge7_link0Z">   
      <visual>   
       <geometry>    
         <cylinder length="53.047805" radius="1.500000"/>    
       </geometry>   
        <origin xyz="0.000000 0.000000 26.523902" rpy="0.000000 0.000000 0.000000"/>   
       <material name="Material_22"> 
         <color rgba="0.541176 0.168627 0.886275 1.000000"/> 
       </material>  
     </visual>   
   </link>    
  <joint name="edge7_link0Z_edge7_link0X" type="fixed">  
    <parent link="edge7_link0Z"/>   
    <child link="edge7_link0X"/>  
    <origin xyz="0.000000 0.000000 53.047805" rpy="0.000000 0.000000 1.868587"/>   
  </joint>   
  <link name="edge7_link0X">   
      <visual>   
       <geometry>    
         <cylinder length="28.656914" radius="1.000000"/>    
       </geometry>   
        <origin xyz="14.328457 0.000000 0.000000" rpy="0.000000 1.570796 0.000000"/>   
       <material name="Material_23"> 
         <color rgba="0.541176 0.168627 0.886275 1.000000"/> 
       </material>  
     </visual>   
   </link>    
  <joint name="edge7_link0X_edge7_link1Z" type="revolute"> 
   <parent link="edge7_link0X"/>    
    <child link="edge7_link1Z"/>   
    <origin xyz="28.656914 0.000000 0.000000" rpy="1.610126 0.000000 0.000000"/>   
   <limit effort="1000.0" lower="-3.14" upper="3.14" velocity="0.5"/>    
  <axis xyz="0.000000 0.000000 1.000000"/>   
   </joint> 
  <link name="edge7_link1Z">   
      <visual>   
       <geometry>    
         <cylinder length="46.889989" radius="1.500000"/>    
       </geometry>   
        <origin xyz="-12.955256 -19.532620 -0.553073" rpy="-1.594389 -0.000000 2.555950"/>   
       <material name="Material_24"> 
         <color rgba="1.000000 1.000000 1.000000 1.000000"/> 
       </material>  
     </visual>   
   </link>    
</robot>